Workbook

Sheet Angles
A1: t [sec] | B1: head.rotation.LR [°] | C1: head.flexion.DU [°] | D1: head.flexion.CCWCW [°] | E1: trunk.rotation.LR [°] | F1: trunk.flexion.FB [°] | G1: trunk.flexion.LR [°] | H1: R.shoulder.flexion.FB [°] | I1: R.shoulder.abduction.CWCCW [°] | J1: L.shoulder.flexion.FB [°] | K1: L.shoulder.abduction.CWCCW [°] | L1: R.elbow.flexion.UD [°] | M1: R.elbow.rotation.PS [°] | N1: L.elbow.flexion.UD [°] | O1: L.elbow.rotation.PS [°] | P1: R.wrist.flexion.UD [°] | Q1: R.wrist.rotation.UR [°] | R1: L.wrist.flexion.UD [°] | S1: L.wrist.rotation.UR [°] | T1: R.knee.flexion.UD [°] | U1: L.knee.flexion.UD [°] | V1: contact points [#] | W1: R.ankle.flexion.UD [°] | X1: L.ankle.flexion.UD [°]
A2: /
A3: 1 | B3: 46 | C3: 21 | D3: -11 | E3: -11 | F3: 65 | G3: 11 | H3: 91 | I3: 61 | J3: 25 | K3: -61 | L3: 28 | M3: 30 | N3: 90 | O3: 65 | P3: 20 | Q3: 3 | R3: 20 | S3: -25 | T3: 65 | U3: 28 | V3: 2
A4: 2 | B4: 47 | C4: 22 | D4: -10 | E4: -10 | F4: 66 | G4: 11 | H4: 92 | I4: 1 | J4: 26 | K4: -59 | L4: 29 | M4: 32 | N4: 91 | O4: 60 | P4: 0 | Q4: 6 | R4: -25 | S4: -18 | T4: 10 | U4: 45 | V4: 2
A5: 3 | B5: 48 | C5: 23 | D5: -9 | E5: -9 | F5: 67 | G5: 11 | H5: 93 | I5: 2 | J5: 27 | K5: -58 | L5: 30 | M5: 34 | N5: 92 | O5: 55 | P5: 1 | Q5: 9 | R5: -24 | S5: -16 | T5: 11 | U5: 46 | V5: 2
A6: 4 | B6: 49 | C6: 24 | D6: -8 | E6: -8 | F6: 68 | G6: 11 | H6: 94 | I6: 3 | J6: 28 | K6: -57 | L6: 31 | M6: 36 | N6: 93 | O6: 50 | P6: 2 | Q6: 12 | R6: -23 | S6: -14 | T6: 12 | U6: 47 | V6: 2
A7: 5 | B7: 50 | C7: 25 | D7: -7 | E7: -7 | F7: 69 | G7: 11 | H7: 95 | I7: 4 | J7: 29 | K7: -56 | L7: 32 | M7: 38 | N7: 94 | O7: 45 | P7: 3 | Q7: 15 | R7: -22 | S7: -12 | T7: 13 | U7: 48 | V7: 1
A8: 6 | B8: 51 | C8: 26 | D8: -6 | E8: -6 | F8: 2 | G8: 11 | H8: 1 | I8: 5 | J8: 30 | K8: -55 | L8: 33 | M8: 40 | N8: 95 | O8: 40 | P8: 4 | Q8: 18 | R8: -21 | S8: -10 | T8: 14 | U8: 49 | V8: 1
A9: 7 | B9: 52 | C9: 27 | D9: -5 | E9: -5 | F9: 2 | G9: 11 | H9: 2 | I9: 6 | J9: 31 | K9: -54 | L9: 34 | M9: 42 | N9: 96 | O9: 35 | P9: 5 | Q9: 21 | R9: -20 | S9: -8 | T9: 15 | U9: 50 | V9: 1
A10: 8 | B10: 53 | C10: 28 | D10: -4 | E10: -4 | F10: 2 | G10: 11 | H10: 3 | I10: 7 | J10: 32 | K10: -53 | L10: 35 | M10: 44 | N10: 97 | O10: 30 | P10: 6 | Q10: 24 | R10: -19 | S10: -6 | T10: 16 | U10: 51 | V10: 1
A11: 9 | B11: 54 | C11: 29 | D11: -3 | E11: -3 | F11: 2 | G11: 11 | H11: 4 | I11: 8 | J11: 33 | K11: -52 | L11: 36 | M11: 46 | N11: 98 | O11: 25 | P11: 7 | Q11: 22 | R11: -18 | S11: -4 | T11: 17 | U11: 52 | V11: 1
A12: 10 | B12: 55 | C12: 30 | D12: -2 | E12: -2 | F12: 2 | G12: 7 | H12: 5 | I12: 9 | J12: 34 | K12: -51 | L12: 37 | M12: 48 | N12: 99 | O12: 20 | P12: 8 | Q12: 20 | R12: -17 | S12: -2 | T12: 18 | U12: 53 | V12: 1
A13: 11 | B13: 56 | C13: 31 | D13: -1 | E13: -1 | F13: 2 | G13: 7 | H13: 6 | I13: 10 | J13: 35 | K13: -50 | L13: 38 | M13: 50 | N13: 100 | O13: 15 | P13: 9 | Q13: 18 | R13: -16 | S13: 0 | T13: 19 | U13: 54 | V13: 1
A14: 12 | B14: 9 | C14: 2 | D14: 0 | E14: 0 | F14: 2 | G14: 7 | H14: 7 | I14: 11 | J14: 36 | K14: -49 | L14: 39 | M14: 52 | N14: 101 | O14: 10 | P14: 10 | Q14: 16 | R14: -15 | S14: 2 | T14: 20 | U14: 55 | V14: 1
... A28: 26 | B28: 23 | C28: 16 | D28: 14 | E28: 14 | F28: 2 | G28: 2 | H28: 21 | I28: 25 | J28: 50 | K28: -35 | L28: 53 | M28: -8 | N28: 115 | O28: -61 | P28: -15 | Q28: -28 | R28: -1 | S28: 30 | T28: 34 | U28: 69 | V28: 2

Sheet Scores
A1: t [sec] | B1: score.head.rotation.LR [°] | C1: score.head.flexion.DU [°] | D1: score.head.flexion.CCWCW [°] | E1: score.trunk.rotation.LR [°] | F1: score.trunk.flexion.FB [°] | G1: score.trunk.flexion.LR [°] | H1: score.R.shoulder.flexion.FB [°] | I1: score.R.shoulder.abduction.CWCCW [°] | J1: score.L.shoulder.flexion.FB [°] | K1: score.L.shoulder.abduction.CWCCW [°] | L1: score.R.elbow.flexion.UD [°] | M1: score.R.elbow.rotation.PS [°] | N1: score.L.elbow.flexion.UD [°] | O1: score.L.elbow.rotation.PS [°] | P1: score.R.wrist.flexion.UD [°] | Q1: score.R.wrist.rotation.UR [°] | R1: score.L.wrist.flexion.UD [°] | S1: score.L.wrist.rotation.UR [°] | T1: score.R.knee.flexion.UD [°] | U1: score.L.knee.flexion.UD [°] | V1: score.contact points [#] | W1: score.R.ankle.flexion.UD [°] | X1: score.L.ankle.flexion.UD [°]
A2: /
A3: =Angles!A3 -> 1 | B3: =IF(A3=0,"", IF(AND(Angles!B3>=-45, Angles!B3<=45), 0, 1)) -> 1 | C3: =IF(A3=0,"",IF(Angles!C3>=0,IF(Angles!C3<=20,1,2),2)) -> 2 | D3: =IF(A3=0,"", IF(AND(Angles!D3>=-10, Angles!D3<=10), 0, 1)) -> 1 | E3: =IF(A3=0,"", IF(AND(Angles!E3>=-10, Angles!E3<=10), 0, 1)) -> 1 | F3: =IF(A3=0,"", IF(Angles!F3<0, 2, IF(Angles!F3<=20, 1, IF(Angles!F3<=60, 2, 3)))) -> 3 | G3: =IF(A3=0,"",IF(AND(Angles!G3>=-10,Angles!G3<=10),0,1)) -> 1 | H3: =IF(A3=0,"",IF(Angles!H3<-20,2,IF(Angles!H3<=20,1,IF(Angles!H3<=60,2,IF(Angles!H3<=90,3,4))))) -> 4 | I3: =IF(A3=0,"",IF(AND(Angles!I3>=-60,Angles!I3<=60),0,1)) -> 1 | J3: =IF(A3=0,"",IF(Angles!J3<-20,2,IF(Angles!J3<=20,1,IF(Angles!J3<=60,2,IF(Angles!J3<=90,3,4))))) -> 2 | K3: =IF(A3=0,"",IF(AND(Angles!K3>=-60,Angles!K3<=60),0,1)) -> 1 | L3: =IF(A3=0,"",IF(AND(Angles!L3>=30,Angles!L3<=170),1,2)) -> 2 | M3: =IF(A3=0,"",IF(AND(Angles!M3>=-60,Angles!M3<=60),0,1)) -> 0 | N3: =IF(A3=0,"",IF(AND(Angles!N3>=30,Angles!N3<=170),1,2)) -> 1 | O3: =IF($A$3=0,"",IF(AND(Angles!O3>=-60,Angles!O3<=60),0,1)) -> 1 | P3: =IF(A3=0,"",IF(AND(Angles!P3>=-15,Angles!P3<=15),1,2)) -> 2 | Q3: =IF($A$3=0,"",IF(AND(Angles!Q3>=-15,Angles!Q3<=24),0,1)) -> 0 | R3: =IF(A3=0,"",IF(AND(Angles!R3>=-15,Angles!R3<=15),1,2)) -> 2 | S3: =IF($A$3=0,"",IF(AND(Angles!S3>=-15,Angles!S3<=24),0,1)) -> 1 | T3: =IF(A3=0,"",IF(Angles!T3<=30,0,IF(Angles!T3<=60,1,2))) -> 2 | U3: =IF(A3=0,"",IF(Angles!U3<=30,0,IF(Angles!U3<=60,1,2))) -> 0 | V3: 2
A4: =Angles!A4 -> 2 | B4: =IF(A4=0,"", IF(AND(Angles!B4>=-45, Angles!B4<=45), 0, 1)) -> 1 | C4: =IF(A4=0,"",IF(Angles!C4>=0,IF(Angles!C4<=20,1,2),2)) -> 2 | D4: =IF(A4=0,"", IF(AND(Angles!D4>=-10, Angles!D4<=10), 0, 1)) -> 0 | E4: =IF(A4=0,"", IF(AND(Angles!E4>=-10, Angles!E4<=10), 0, 1)) -> 0 | F4: =IF(A4=0,"", IF(Angles!F4<0, 2, IF(Angles!F4<=20, 1, IF(Angles!F4<=60, 2, 3)))) -> 3 | G4: =IF(A4=0,"",IF(AND(Angles!G4>=-10,Angles!G4<=10),0,1)) -> 1 | H4: =IF(A4=0,"",IF(Angles!H4<-20,2,IF(Angles!H4<=20,1,IF(Angles!H4<=60,2,IF(Angles!H4<=90,3,4))))) -> 4 | I4: =IF(A4=0,"",IF(AND(Angles!I4>=-60,Angles!I4<=60),0,1)) -> 0 | J4: =IF(A4=0,"",IF(Angles!J4<-20,2,IF(Angles!J4<=20,1,IF(Angles!J4<=60,2,IF(Angles!J4<=90,3,4))))) -> 2 | K4: =IF(A4=0,"",IF(AND(Angles!K4>=-60,Angles!K4<=60),0,1)) -> 0 | L4: =IF(A4=0,"",IF(AND(Angles!L4>=30,Angles!L4<=170),1,2)) -> 2 | M4: =IF($A$3=0,"",IF(AND(Angles!M4>=-60,Angles!M4<=60),0,1)) -> 0 | N4: =IF(A4=0,"",IF(AND(Angles!N4>=30,Angles!N4<=170),1,2)) -> 1 | O4: =IF($A$3=0,"",IF(AND(Angles!O4>=-60,Angles!O4<=60),0,1)) -> 0 | P4: =IF(A4=0,"",IF(AND(Angles!P4>=-15,Angles!P4<=15),1,2)) -> 1 | Q4: =IF($A$3=0,"",IF(AND(Angles!Q4>=-15,Angles!Q4<=24),0,1)) -> 0 | R4: =IF(A4=0,"",IF(AND(Angles!R4>=-15,Angles!R4<=15),1,2)) -> 2 | S4: =IF($A$3=0,"",IF(AND(Angles!S4>=-15,Angles!S4<=24),0,1)) -> 1 | T4: =IF(A4=0,"",IF(Angles!T4<=30,0,IF(Angles!T4<=60,1,2))) -> 0 | U4: =IF(A4=0,"",IF(Angles!U4<=30,0,IF(Angles!U4<=60,1,2))) -> 1 | V4: 2
A5: =Angles!A5 -> 3 | B5: =IF(A5=0,"", IF(AND(Angles!B5>=-45, Angles!B5<=45), 0, 1)) -> 1 | C5: =IF(A5=0,"",IF(Angles!C5>=0,IF(Angles!C5<=20,1,2),2)) -> 2 | D5: =IF(A5=0,"", IF(AND(Angles!D5>=-10, Angles!D5<=10), 0, 1)) -> 0 | E5: =IF(A5=0,"", IF(AND(Angles!E5>=-10, Angles!E5<=10), 0, 1)) -> 0 | F5: =IF(A5=0,"", IF(Angles!F5<0, 2, IF(Angles!F5<=20, 1, IF(Angles!F5<=60, 2, 3)))) -> 3 | G5: =IF(A5=0,"",IF(AND(Angles!G5>=-10,Angles!G5<=10),0,1)) -> 1 | H5: =IF(A5=0,"",IF(Angles!H5<-20,2,IF(Angles!H5<=20,1,IF(Angles!H5<=60,2,IF(Angles!H5<=90,3,4))))) -> 4 | I5: =IF(A5=0,"",IF(AND(Angles!I5>=-60,Angles!I5<=60),0,1)) -> 0 | J5: =IF(A5=0,"",IF(Angles!J5<-20,2,IF(Angles!J5<=20,1,IF(Angles!J5<=60,2,IF(Angles!J5<=90,3,4))))) -> 2 | K5: =IF(A5=0,"",IF(AND(Angles!K5>=-60,Angles!K5<=60),0,1)) -> 0 | L5: =IF(A5=0,"",IF(AND(Angles!L5>=30,Angles!L5<=170),1,2)) -> 1 | M5: =IF($A$3=0,"",IF(AND(Angles!M5>=-60,Angles!M5<=60),0,1)) -> 0 | N5: =IF(A5=0,"",IF(AND(Angles!N5>=30,Angles!N5<=170),1,2)) -> 1 | O5: =IF($A$3=0,"",IF(AND(Angles!O5>=-60,Angles!O5<=60),0,1)) -> 0 | P5: =IF(A5=0,"",IF(AND(Angles!P5>=-15,Angles!P5<=15),1,2)) -> 1 | Q5: =IF($A$3=0,"",IF(AND(Angles!Q5>=-15,Angles!Q5<=24),0,1)) -> 0 | R5: =IF(A5=0,"",IF(AND(Angles!R5>=-15,Angles!R5<=15),1,2)) -> 2 | S5: =IF($A$3=0,"",IF(AND(Angles!S5>=-15,Angles!S5<=24),0,1)) -> 1 | T5: =IF(A5=0,"",IF(Angles!T5<=30,0,IF(Angles!T5<=60,1,2))) -> 0 | U5: =IF(A5=0,"",IF(Angles!U5<=30,0,IF(Angles!U5<=60,1,2))) -> 1 | V5: 2
A6: =Angles!A6 -> 4 | B6: =IF(A6=0,"", IF(AND(Angles!B6>=-45, Angles!B6<=45), 0, 1)) -> 1 | C6: =IF(A6=0,"",IF(Angles!C6>=0,IF(Angles!C6<=20,1,2),2)) -> 2 | D6: =IF(A6=0,"", IF(AND(Angles!D6>=-10, Angles!D6<=10), 0, 1)) -> 0 | E6: =IF(A6=0,"", IF(AND(Angles!E6>=-10, Angles!E6<=10), 0, 1)) -> 0 | F6: =IF(A6=0,"", IF(Angles!F6<0, 2, IF(Angles!F6<=20, 1, IF(Angles!F6<=60, 2, 3)))) -> 3 | G6: =IF(A6=0,"",IF(AND(Angles!G6>=-10,Angles!G6<=10),0,1)) -> 1 | H6: =IF(A6=0,"",IF(Angles!H6<-20,2,IF(Angles!H6<=20,1,IF(Angles!H6<=60,2,IF(Angles!H6<=90,3,4))))) -> 4 | I6: =IF(A6=0,"",IF(AND(Angles!I6>=-60,Angles!I6<=60),0,1)) -> 0 | J6: =IF(A6=0,"",IF(Angles!J6<-20,2,IF(Angles!J6<=20,1,IF(Angles!J6<=60,2,IF(Angles!J6<=90,3,4))))) -> 2 | K6: =IF(A6=0,"",IF(AND(Angles!K6>=-60,Angles!K6<=60),0,1)) -> 0 | L6: =IF(A6=0,"",IF(AND(Angles!L6>=30,Angles!L6<=170),1,2)) -> 1 | M6: =IF($A$3=0,"",IF(AND(Angles!M6>=-60,Angles!M6<=60),0,1)) -> 0 | N6: =IF(A6=0,"",IF(AND(Angles!N6>=30,Angles!N6<=170),1,2)) -> 1 | O6: =IF($A$3=0,"",IF(AND(Angles!O6>=-60,Angles!O6<=60),0,1)) -> 0 | P6: =IF(A6=0,"",IF(AND(Angles!P6>=-15,Angles!P6<=15),1,2)) -> 1 | Q6: =IF($A$3=0,"",IF(AND(Angles!Q6>=-15,Angles!Q6<=24),0,1)) -> 0 | R6: =IF(A6=0,"",IF(AND(Angles!R6>=-15,Angles!R6<=15),1,2)) -> 2 | S6: =IF($A$3=0,"",IF(AND(Angles!S6>=-15,Angles!S6<=24),0,1)) -> 0 | T6: =IF(A6=0,"",IF(Angles!T6<=30,0,IF(Angles!T6<=60,1,2))) -> 0 | U6: =IF(A6=0,"",IF(Angles!U6<=30,0,IF(Angles!U6<=60,1,2))) -> 1 | V6: 2
A7: =Angles!A7 -> 5 | B7: =IF(A7=0,"", IF(AND(Angles!B7>=-45, Angles!B7<=45), 0, 1)) -> 1 | C7: =IF(A7=0,"",IF(Angles!C7>=0,IF(Angles!C7<=20,1,2),2)) -> 2 | D7: =IF(A7=0,"", IF(AND(Angles!D7>=-10, Angles!D7<=10), 0, 1)) -> 0 | E7: =IF(A7=0,"", IF(AND(Angles!E7>=-10, Angles!E7<=10), 0, 1)) -> 0 | F7: =IF(A7=0,"", IF(Angles!F7<0, 2, IF(Angles!F7<=20, 1, IF(Angles!F7<=60, 2, 3)))) -> 3 | G7: =IF(A7=0,"",IF(AND(Angles!G7>=-10,Angles!G7<=10),0,1)) -> 1 | H7: =IF(A7=0,"",IF(Angles!H7<-20,2,IF(Angles!H7<=20,1,IF(Angles!H7<=60,2,IF(Angles!H7<=90,3,4))))) -> 4 | I7: =IF(A7=0,"",IF(AND(Angles!I7>=-60,Angles!I7<=60),0,1)) -> 0 | J7: =IF(A7=0,"",IF(Angles!J7<-20,2,IF(Angles!J7<=20,1,IF(Angles!J7<=60,2,IF(Angles!J7<=90,3,4))))) -> 2 | K7: =IF(A7=0,"",IF(AND(Angles!K7>=-60,Angles!K7<=60),0,1)) -> 0 | L7: =IF(A7=0,"",IF(AND(Angles!L7>=30,Angles!L7<=170),1,2)) -> 1 | M7: =IF($A$3=0,"",IF(AND(Angles!M7>=-60,Angles!M7<=60),0,1)) -> 0 | N7: =IF(A7=0,"",IF(AND(Angles!N7>=30,Angles!N7<=170),1,2)) -> 1 | O7: =IF($A$3=0,"",IF(AND(Angles!O7>=-60,Angles!O7<=60),0,1)) -> 0 | P7: =IF(A7=0,"",IF(AND(Angles!P7>=-15,Angles!P7<=15),1,2)) -> 1 | Q7: =IF($A$3=0,"",IF(AND(Angles!Q7>=-15,Angles!Q7<=24),0,1)) -> 0 | R7: =IF(A7=0,"",IF(AND(Angles!R7>=-15,Angles!R7<=15),1,2)) -> 2 | S7: =IF($A$3=0,"",IF(AND(Angles!S7>=-15,Angles!S7<=24),0,1)) -> 0 | T7: =IF(A7=0,"",IF(Angles!T7<=30,0,IF(Angles!T7<=60,1,2))) -> 0 | U7: =IF(A7=0,"",IF(Angles!U7<=30,0,IF(Angles!U7<=60,1,2))) -> 1 | V7: 1
A8: =Angles!A8 -> 6 | B8: =IF(A8=0,"", IF(AND(Angles!B8>=-45, Angles!B8<=45), 0, 1)) -> 1 | C8: =IF(A8=0,"",IF(Angles!C8>=0,IF(Angles!C8<=20,1,2),2)) -> 2 | D8: =IF(A8=0,"", IF(AND(Angles!D8>=-10, Angles!D8<=10), 0, 1)) -> 0 | E8: =IF(A8=0,"", IF(AND(Angles!E8>=-10, Angles!E8<=10), 0, 1)) -> 0 | F8: =IF(A8=0,"", IF(Angles!F8<0, 2, IF(Angles!F8<=20, 1, IF(Angles!F8<=60, 2, 3)))) -> 1 | G8: =IF(A8=0,"",IF(AND(Angles!G8>=-10,Angles!G8<=10),0,1)) -> 1 | H8: =IF(A8=0,"",IF(Angles!H8<-20,2,IF(Angles!H8<=20,1,IF(Angles!H8<=60,2,IF(Angles!H8<=90,3,4))))) -> 1 | I8: =IF(A8=0,"",IF(AND(Angles!I8>=-60,Angles!I8<=60),0,1)) -> 0 | J8: =IF(A8=0,"",IF(Angles!J8<-20,2,IF(Angles!J8<=20,1,IF(Angles!J8<=60,2,IF(Angles!J8<=90,3,4))))) -> 2 | K8: =IF(A8=0,"",IF(AND(Angles!K8>=-60,Angles!K8<=60),0,1)) -> 0 | L8: =IF(A8=0,"",IF(AND(Angles!L8>=30,Angles!L8<=170),1,2)) -> 1 | M8: =IF($A$3=0,"",IF(AND(Angles!M8>=-60,Angles!M8<=60),0,1)) -> 0 | N8: =IF(A8=0,"",IF(AND(Angles!N8>=30,Angles!N8<=170),1,2)) -> 1 | O8: =IF($A$3=0,"",IF(AND(Angles!O8>=-60,Angles!O8<=60),0,1)) -> 0 | P8: =IF(A8=0,"",IF(AND(Angles!P8>=-15,Angles!P8<=15),1,2)) -> 1 | Q8: =IF($A$3=0,"",IF(AND(Angles!Q8>=-15,Angles!Q8<=24),0,1)) -> 0 | R8: =IF(A8=0,"",IF(AND(Angles!R8>=-15,Angles!R8<=15),1,2)) -> 2 | S8: =IF($A$3=0,"",IF(AND(Angles!S8>=-15,Angles!S8<=24),0,1)) -> 0 | T8: =IF(A8=0,"",IF(Angles!T8<=30,0,IF(Angles!T8<=60,1,2))) -> 0 | U8: =IF(A8=0,"",IF(Angles!U8<=30,0,IF(Angles!U8<=60,1,2))) -> 1 | V8: 1
A9: =Angles!A9 -> 7 | B9: =IF(A9=0,"", IF(AND(Angles!B9>=-45, Angles!B9<=45), 0, 1)) -> 1 | C9: =IF(A9=0,"",IF(Angles!C9>=0,IF(Angles!C9<=20,1,2),2)) -> 2 | D9: =IF(A9=0,"", IF(AND(Angles!D9>=-10, Angles!D9<=10), 0, 1)) -> 0 | E9: =IF(A9=0,"", IF(AND(Angles!E9>=-10, Angles!E9<=10), 0, 1)) -> 0 | F9: =IF(A9=0,"", IF(Angles!F9<0, 2, IF(Angles!F9<=20, 1, IF(Angles!F9<=60, 2, 3)))) -> 1 | G9: =IF(A9=0,"",IF(AND(Angles!G9>=-10,Angles!G9<=10),0,1)) -> 1 | H9: =IF(A9=0,"",IF(Angles!H9<-20,2,IF(Angles!H9<=20,1,IF(Angles!H9<=60,2,IF(Angles!H9<=90,3,4))))) -> 1 | I9: =IF(A9=0,"",IF(AND(Angles!I9>=-60,Angles!I9<=60),0,1)) -> 0 | J9: =IF(A9=0,"",IF(Angles!J9<-20,2,IF(Angles!J9<=20,1,IF(Angles!J9<=60,2,IF(Angles!J9<=90,3,4))))) -> 2 | K9: =IF(A9=0,"",IF(AND(Angles!K9>=-60,Angles!K9<=60),0,1)) -> 0 | L9: =IF(A9=0,"",IF(AND(Angles!L9>=30,Angles!L9<=170),1,2)) -> 1 | M9: =IF($A$3=0,"",IF(AND(Angles!M9>=-60,Angles!M9<=60),0,1)) -> 0 | N9: =IF(A9=0,"",IF(AND(Angles!N9>=30,Angles!N9<=170),1,2)) -> 1 | O9: =IF($A$3=0,"",IF(AND(Angles!O9>=-60,Angles!O9<=60),0,1)) -> 0 | P9: =IF(A9=0,"",IF(AND(Angles!P9>=-15,Angles!P9<=15),1,2)) -> 1 | Q9: =IF($A$3=0,"",IF(AND(Angles!Q9>=-15,Angles!Q9<=24),0,1)) -> 0 | R9: =IF(A9=0,"",IF(AND(Angles!R9>=-15,Angles!R9<=15),1,2)) -> 2 | S9: =IF($A$3=0,"",IF(AND(Angles!S9>=-15,Angles!S9<=24),0,1)) -> 0 | T9: =IF(A9=0,"",IF(Angles!T9<=30,0,IF(Angles!T9<=60,1,2))) -> 0 | U9: =IF(A9=0,"",IF(Angles!U9<=30,0,IF(Angles!U9<=60,1,2))) -> 1 | V9: 1
A10: =Angles!A10 -> 8 | B10: =IF(A10=0,"", IF(AND(Angles!B10>=-45, Angles!B10<=45), 0, 1)) -> 1 | C10: =IF(A10=0,"",IF(Angles!C10>=0,IF(Angles!C10<=20,1,2),2)) -> 2 | D10: =IF(A10=0,"", IF(AND(Angles!D10>=-10, Angles!D10<=10), 0, 1)) -> 0 | E10: =IF(A10=0,"", IF(AND(Angles!E10>=-10, Angles!E10<=10), 0, 1)) -> 0 | F10: =IF(A10=0,"", IF(Angles!F10<0, 2, IF(Angles!F10<=20, 1, IF(Angles!F10<=60, 2, 3)))) -> 1 | G10: =IF(A10=0,"",IF(AND(Angles!G10>=-10,Angles!G10<=10),0,1)) -> 1 | H10: =IF(A10=0,"",IF(Angles!H10<-20,2,IF(Angles!H10<=20,1,IF(Angles!H10<=60,2,IF(Angles!H10<=90,3,4))))) -> 1 | I10: =IF(A10=0,"",IF(AND(Angles!I10>=-60,Angles!I10<=60),0,1)) -> 0 | J10: =IF(A10=0,"",IF(Angles!J10<-20,2,IF(Angles!J10<=20,1,IF(Angles!J10<=60,2,IF(Angles!J10<=90,3,4))))) -> 2 | K10: =IF(A10=0,"",IF(AND(Angles!K10>=-60,Angles!K10<=60),0,1)) -> 0 | L10: =IF(A10=0,"",IF(AND(Angles!L10>=30,Angles!L10<=170),1,2)) -> 1 | M10: =IF($A$3=0,"",IF(AND(Angles!M10>=-60,Angles!M10<=60),0,1)) -> 0 | N10: =IF(A10=0,"",IF(AND(Angles!N10>=30,Angles!N10<=170),1,2)) -> 1 | O10: =IF($A$3=0,"",IF(AND(Angles!O10>=-60,Angles!O10<=60),0,1)) -> 0 | P10: =IF(A10=0,"",IF(AND(Angles!P10>=-15,Angles!P10<=15),1,2)) -> 1 | Q10: =IF($A$3=0,"",IF(AND(Angles!Q10>=-15,Angles!Q10<=24),0,1)) -> 0 | R10: =IF(A10=0,"",IF(AND(Angles!R10>=-15,Angles!R10<=15),1,2)) -> 2 | S10: =IF($A$3=0,"",IF(AND(Angles!S10>=-15,Angles!S10<=24),0,1)) -> 0 | T10: =IF(A10=0,"",IF(Angles!T10<=30,0,IF(Angles!T10<=60,1,2))) -> 0 | U10: =IF(A10=0,"",IF(Angles!U10<=30,0,IF(Angles!U10<=60,1,2))) -> 1 | V10: 1
A11: =Angles!A11 -> 9 | B11: =IF(A11=0,"", IF(AND(Angles!B11>=-45, Angles!B11<=45), 0, 1)) -> 1 | C11: =IF(A11=0,"",IF(Angles!C11>=0,IF(Angles!C11<=20,1,2),2)) -> 2 | D11: =IF(A11=0,"", IF(AND(Angles!D11>=-10, Angles!D11<=10), 0, 1)) -> 0 | E11: =IF(A11=0,"", IF(AND(Angles!E11>=-10, Angles!E11<=10), 0, 1)) -> 0 | F11: =IF(A11=0,"", IF(Angles!F11<0, 2, IF(Angles!F11<=20, 1, IF(Angles!F11<=60, 2, 3)))) -> 1 | G11: =IF(A11=0,"",IF(AND(Angles!G11>=-10,Angles!G11<=10),0,1)) -> 1 | H11: =IF(A11=0,"",IF(Angles!H11<-20,2,IF(Angles!H11<=20,1,IF(Angles!H11<=60,2,IF(Angles!H11<=90,3,4))))) -> 1 | I11: =IF(A11=0,"",IF(AND(Angles!I11>=-60,Angles!I11<=60),0,1)) -> 0 | J11: =IF(A11=0,"",IF(Angles!J11<-20,2,IF(Angles!J11<=20,1,IF(Angles!J11<=60,2,IF(Angles!J11<=90,3,4))))) -> 2 | K11: =IF(A11=0,"",IF(AND(Angles!K11>=-60,Angles!K11<=60),0,1)) -> 0 | L11: =IF(A11=0,"",IF(AND(Angles!L11>=30,Angles!L11<=170),1,2)) -> 1 | M11: =IF($A$3=0,"",IF(AND(Angles!M11>=-60,Angles!M11<=60),0,1)) -> 0 | N11: =IF(A11=0,"",IF(AND(Angles!N11>=30,Angles!N11<=170),1,2)) -> 1 | O11: =IF($A$3=0,"",IF(AND(Angles!O11>=-60,Angles!O11<=60),0,1)) -> 0 | P11: =IF(A11=0,"",IF(AND(Angles!P11>=-15,Angles!P11<=15),1,2)) -> 1 | Q11: =IF($A$3=0,"",IF(AND(Angles!Q11>=-15,Angles!Q11<=24),0,1)) -> 0 | R11: =IF(A11=0,"",IF(AND(Angles!R11>=-15,Angles!R11<=15),1,2)) -> 2 | S11: =IF($A$3=0,"",IF(AND(Angles!S11>=-15,Angles!S11<=24),0,1)) -> 0 | T11: =IF(A11=0,"",IF(Angles!T11<=30,0,IF(Angles!T11<=60,1,2))) -> 0 | U11: =IF(A11=0,"",IF(Angles!U11<=30,0,IF(Angles!U11<=60,1,2))) -> 1 | V11: 1
A12: =Angles!A12 -> 10 | B12: =IF(A12=0,"", IF(AND(Angles!B12>=-45, Angles!B12<=45), 0, 1)) -> 1 | C12: =IF(A12=0,"",IF(Angles!C12>=0,IF(Angles!C12<=20,1,2),2)) -> 2 | D12: =IF(A12=0,"", IF(AND(Angles!D12>=-10, Angles!D12<=10), 0, 1)) -> 0 | E12: =IF(A12=0,"", IF(AND(Angles!E12>=-10, Angles!E12<=10), 0, 1)) -> 0 | F12: =IF(A12=0,"", IF(Angles!F12<0, 2, IF(Angles!F12<=20, 1, IF(Angles!F12<=60, 2, 3)))) -> 1 | G12: =IF(A12=0,"",IF(AND(Angles!G12>=-10,Angles!G12<=10),0,1)) -> 0 | H12: =IF(A12=0,"",IF(Angles!H12<-20,2,IF(Angles!H12<=20,1,IF(Angles!H12<=60,2,IF(Angles!H12<=90,3,4))))) -> 1 | I12: =IF(A12=0,"",IF(AND(Angles!I12>=-60,Angles!I12<=60),0,1)) -> 0 | J12: =IF(A12=0,"",IF(Angles!J12<-20,2,IF(Angles!J12<=20,1,IF(Angles!J12<=60,2,IF(Angles!J12<=90,3,4))))) -> 2 | K12: =IF(A12=0,"",IF(AND(Angles!K12>=-60,Angles!K12<=60),0,1)) -> 0 | L12: =IF(A12=0,"",IF(AND(Angles!L12>=30,Angles!L12<=170),1,2)) -> 1 | M12: =IF($A$3=0,"",IF(AND(Angles!M12>=-60,Angles!M12<=60),0,1)) -> 0 | N12: =IF(A12=0,"",IF(AND(Angles!N12>=30,Angles!N12<=170),1,2)) -> 1 | O12: =IF($A$3=0,"",IF(AND(Angles!O12>=-60,Angles!O12<=60),0,1)) -> 0 | P12: =IF(A12=0,"",IF(AND(Angles!P12>=-15,Angles!P12<=15),1,2)) -> 1 | Q12: =IF($A$3=0,"",IF(AND(Angles!Q12>=-15,Angles!Q12<=24),0,1)) -> 0 | R12: =IF(A12=0,"",IF(AND(Angles!R12>=-15,Angles!R12<=15),1,2)) -> 2 | S12: =IF($A$3=0,"",IF(AND(Angles!S12>=-15,Angles!S12<=24),0,1)) -> 0 | T12: =IF(A12=0,"",IF(Angles!T12<=30,0,IF(Angles!T12<=60,1,2))) -> 0 | U12: =IF(A12=0,"",IF(Angles!U12<=30,0,IF(Angles!U12<=60,1,2))) -> 1 | V12: 1
A13: =Angles!A13 -> 11 | B13: =IF(A13=0,"", IF(AND(Angles!B13>=-45, Angles!B13<=45), 0, 1)) -> 1 | C13: =IF(A13=0,"",IF(Angles!C13>=0,IF(Angles!C13<=20,1,2),2)) -> 2 | D13: =IF(A13=0,"", IF(AND(Angles!D13>=-10, Angles!D13<=10), 0, 1)) -> 0 | E13: =IF(A13=0,"", IF(AND(Angles!E13>=-10, Angles!E13<=10), 0, 1)) -> 0 | F13: =IF(A13=0,"", IF(Angles!F13<0, 2, IF(Angles!F13<=20, 1, IF(Angles!F13<=60, 2, 3)))) -> 1 | G13: =IF(A13=0,"",IF(AND(Angles!G13>=-10,Angles!G13<=10),0,1)) -> 0 | H13: =IF(A13=0,"",IF(Angles!H13<-20,2,IF(Angles!H13<=20,1,IF(Angles!H13<=60,2,IF(Angles!H13<=90,3,4))))) -> 1 | I13: =IF(A13=0,"",IF(AND(Angles!I13>=-60,Angles!I13<=60),0,1)) -> 0 | J13: =IF(A13=0,"",IF(Angles!J13<-20,2,IF(Angles!J13<=20,1,IF(Angles!J13<=60,2,IF(Angles!J13<=90,3,4))))) -> 2 | K13: =IF(A13=0,"",IF(AND(Angles!K13>=-60,Angles!K13<=60),0,1)) -> 0 | L13: =IF(A13=0,"",IF(AND(Angles!L13>=30,Angles!L13<=170),1,2)) -> 1 | M13: =IF($A$3=0,"",IF(AND(Angles!M13>=-60,Angles!M13<=60),0,1)) -> 0 | N13: =IF(A13=0,"",IF(AND(Angles!N13>=30,Angles!N13<=170),1,2)) -> 1 | O13: =IF($A$3=0,"",IF(AND(Angles!O13>=-60,Angles!O13<=60),0,1)) -> 0 | P13: =IF(A13=0,"",IF(AND(Angles!P13>=-15,Angles!P13<=15),1,2)) -> 1 | Q13: =IF($A$3=0,"",IF(AND(Angles!Q13>=-15,Angles!Q13<=24),0,1)) -> 0 | R13: =IF(A13=0,"",IF(AND(Angles!R13>=-15,Angles!R13<=15),1,2)) -> 2 | S13: =IF($A$3=0,"",IF(AND(Angles!S13>=-15,Angles!S13<=24),0,1)) -> 0 | T13: =IF(A13=0,"",IF(Angles!T13<=30,0,IF(Angles!T13<=60,1,2))) -> 0 | U13: =IF(A13=0,"",IF(Angles!U13<=30,0,IF(Angles!U13<=60,1,2))) -> 1 | V13: 1
A14: =Angles!A14 -> 12 | B14: =IF(A14=0,"", IF(AND(Angles!B14>=-45, Angles!B14<=45), 0, 1)) -> 0 | C14: =IF(A14=0,"",IF(Angles!C14>=0,IF(Angles!C14<=20,1,2),2)) -> 1 | D14: =IF(A14=0,"", IF(AND(Angles!D14>=-10, Angles!D14<=10), 0, 1)) -> 0 | E14: =IF(A14=0,"", IF(AND(Angles!E14>=-10, Angles!E14<=10), 0, 1)) -> 0 | F14: =IF(A14=0,"", IF(Angles!F14<0, 2, IF(Angles!F14<=20, 1, IF(Angles!F14<=60, 2, 3)))) -> 1 | G14: =IF(A14=0,"",IF(AND(Angles!G14>=-10,Angles!G14<=10),0,1)) -> 0 | H14: =IF(A14=0,"",IF(Angles!H14<-20,2,IF(Angles!H14<=20,1,IF(Angles!H14<=60,2,IF(Angles!H14<=90,3,4))))) -> 1 | I14: =IF(A14=0,"",IF(AND(Angles!I14>=-60,Angles!I14<=60),0,1)) -> 0 | J14: =IF(A14=0,"",IF(Angles!J14<-20,2,IF(Angles!J14<=20,1,IF(Angles!J14<=60,2,IF(Angles!J14<=90,3,4))))) -> 2 | K14: =IF(A14=0,"",IF(AND(Angles!K14>=-60,Angles!K14<=60),0,1)) -> 0 | L14: =IF(A14=0,"",IF(AND(Angles!L14>=30,Angles!L14<=170),1,2)) -> 1 | M14: =IF($A$3=0,"",IF(AND(Angles!M14>=-60,Angles!M14<=60),0,1)) -> 0 | N14: =IF(A14=0,"",IF(AND(Angles!N14>=30,Angles!N14<=170),1,2)) -> 1 | O14: =IF($A$3=0,"",IF(AND(Angles!O14>=-60,Angles!O14<=60),0,1)) -> 0 | P14: =IF(A14=0,"",IF(AND(Angles!P14>=-15,Angles!P14<=15),1,2)) -> 1 | Q14: =IF($A$3=0,"",IF(AND(Angles!Q14>=-15,Angles!Q14<=24),0,1)) -> 0 | R14: =IF(A14=0,"",IF(AND(Angles!R14>=-15,Angles!R14<=15),1,2)) -> 1 | S14: =IF($A$3=0,"",IF(AND(Angles!S14>=-15,Angles!S14<=24),0,1)) -> 0 | T14: =IF(A14=0,"",IF(Angles!T14<=30,0,IF(Angles!T14<=60,1,2))) -> 0 | U14: =IF(A14=0,"",IF(Angles!U14<=30,0,IF(Angles!U14<=60,1,2))) -> 1 | V14: 1
A15: =Angles!A15 -> 13 | B15: =IF(A15=0,"", IF(AND(Angles!B15>=-45, Angles!B15<=45), 0, 1)) -> 0 | C15: =IF(A15=0,"",IF(Angles!C15>=0,IF(Angles!C15<=20,1,2),2)) -> 1 | D15: =IF(A15=0,"", IF(AND(Angles!D15>=-10, Angles!D15<=10), 0, 1)) -> 0 | E15: =IF(A15=0,"", IF(AND(Angles!E15>=-10, Angles!E15<=10), 0, 1)) -> 0 | F15: =IF(A15=0,"", IF(Angles!F15<0, 2, IF(Angles!F15<=20, 1, IF(Angles!F15<=60, 2, 3)))) -> 1 | G15: =IF(A15=0,"",IF(AND(Angles!G15>=-10,Angles!G15<=10),0,1)) -> 0 | H15: =IF(A15=0,"",IF(Angles!H15<-20,2,IF(Angles!H15<=20,1,IF(Angles!H15<=60,2,IF(Angles!H15<=90,3,4))))) -> 1 | I15: =IF(A15=0,"",IF(AND(Angles!I15>=-60,Angles!I15<=60),0,1)) -> 0 | J15: =IF(A15=0,"",IF(Angles!J15<-20,2,IF(Angles!J15<=20,1,IF(Angles!J15<=60,2,IF(Angles!J15<=90,3,4))))) -> 2 | K15: =IF(A15=0,"",IF(AND(Angles!K15>=-60,Angles!K15<=60),0,1)) -> 0 | L15: =IF(A15=0,"",IF(AND(Angles!L15>=30,Angles!L15<=170),1,2)) -> 1 | M15: =IF($A$3=0,"",IF(AND(Angles!M15>=-60,Angles!M15<=60),0,1)) -> 0 | N15: =IF(A15=0,"",IF(AND(Angles!N15>=30,Angles!N15<=170),1,2)) -> 1 | O15: =IF($A$3=0,"",IF(AND(Angles!O15>=-60,Angles!O15<=60),0,1)) -> 0 | P15: =IF(A15=0,"",IF(AND(Angles!P15>=-15,Angles!P15<=15),1,2)) -> 1 | Q15: =IF($A$3=0,"",IF(AND(Angles!Q15>=-15,Angles!Q15<=24),0,1)) -> 0 | R15: =IF(A15=0,"",IF(AND(Angles!R15>=-15,Angles!R15<=15),1,2)) -> 1 | S15: =IF($A$3=0,"",IF(AND(Angles!S15>=-15,Angles!S15<=24),0,1)) -> 0 | T15: =IF(A15=0,"",IF(Angles!T15<=30,0,IF(Angles!T15<=60,1,2))) -> 0 | U15: =IF(A15=0,"",IF(Angles!U15<=30,0,IF(Angles!U15<=60,1,2))) -> 1 | V15: 1
... A28: =Angles!A28 -> 26 | B28: =IF(A28=0,"", IF(AND(Angles!B28>=-45, Angles!B28<=45), 0, 1)) -> 0 | C28: =IF(A28=0,"",IF(Angles!C28>=0,IF(Angles!C28<=20,1,2),2)) -> 1 | D28: =IF(A28=0,"", IF(AND(Angles!D28>=-10, Angles!D28<=10), 0, 1)) -> 1 | E28: =IF(A28=0,"", IF(AND(Angles!E28>=-10, Angles!E28<=10), 0, 1)) -> 1 | F28: =IF(A28=0,"", IF(Angles!F28<0, 2, IF(Angles!F28<=20, 1, IF(Angles!F28<=60, 2, 3)))) -> 1 | G28: =IF(A28=0,"",IF(AND(Angles!G28>=-10,Angles!G28<=10),0,1)) -> 0 | H28: =IF(A28=0,"",IF(Angles!H28<-20,2,IF(Angles!H28<=20,1,IF(Angles!H28<=60,2,IF(Angles!H28<=90,3,4))))) -> 2 | I28: =IF(A28=0,"",IF(AND(Angles!I28>=-60,Angles!I28<=60),0,1)) -> 0 | J28: =IF(A28=0,"",IF(Angles!J28<-20,2,IF(Angles!J28<=20,1,IF(Angles!J28<=60,2,IF(Angles!J28<=90,3,4))))) -> 2 | K28: =IF(A28=0,"",IF(AND(Angles!K28>=-60,Angles!K28<=60),0,1)) -> 0 | L28: =IF(A28=0,"",IF(AND(Angles!L28>=30,Angles!L28<=170),1,2)) -> 1 | M28: =IF($A$3=0,"",IF(AND(Angles!M28>=-60,Angles!M28<=60),0,1)) -> 0 | N28: =IF(A28=0,"",IF(AND(Angles!N28>=30,Angles!N28<=170),1,2)) -> 1 | O28: =IF($A$3=0,"",IF(AND(Angles!O28>=-60,Angles!O28<=60),0,1)) -> 1 | P28: =IF(A28=0,"",IF(AND(Angles!P28>=-15,Angles!P28<=15),1,2)) -> 1 | Q28: =IF($A$3=0,"",IF(AND(Angles!Q28>=-15,Angles!Q28<=24),0,1)) -> 1 | R28: =IF(A28=0,"",IF(AND(Angles!R28>=-15,Angles!R28<=15),1,2)) -> 1 | S28: =IF($A$3=0,"",IF(AND(Angles!S28>=-15,Angles!S28<=24),0,1)) -> 1 | T28: =IF(A28=0,"",IF(Angles!T28<=30,0,IF(Angles!T28<=60,1,2))) -> 1 | U28: =IF(A28=0,"",IF(Angles!U28<=30,0,IF(Angles!U28<=60,1,2))) -> 2 | V28: 2
M29: =IF(B29=0,"",IF(AND(Angles!M29>=-60,Angles!M29<=60),0,1))

Sheet Reba
A1: t [sec] | B1: score.neck | C1: score.trunk | D1: score.R.shoulder | E1: score.L.shoulder | F1: score.shoulder | G1: score.R.elbow | H1: score.L.elbow | I1: score.elbows | J1: score.R.wrist | K1: score.L.wrist | L1: score.wrists | M1: score.R.leg | N1: score.L.leg | O1: score.legs | P1: score.TableA | Q1: score.TableB | R1: score.TableA.mean | S1: score.TableB.mean | T1: score.TableA.Tot | U1: score.TableB.Tot | V1: score.TableC | W1: score.REBA
A3: =Angles!A3 -> 1 | B3: =IF(A3=0,0,IF(Scores!B3+Scores!C3+Scores!D3=1,1,IF(Scores!B3+Scores!C3+Scores!D3=2,2,IF(Scores!B3+Scores!C3+Scores!D3>=3,3,0)))) -> 3 | C3: =Scores!E3+Scores!F3+Scores!G3 -> 5 | D3: =Scores!H3+Scores!I3 -> 5 | E3: =Scores!J3+Scores!K3 -> 3 | F3: =IF(D3>E3,D3,E3) -> 5 | G3: =Scores!L3 -> 2 | H3: =Scores!N3 -> 1 | I3: =IF(A3=0,0,IF(G3>H3,G3,H3)) -> 2 | J3: =Scores!P3+MAX(Scores!Q3,Scores!M3) -> 2 | K3: =Scores!R3+MAX(Scores!S3,Scores!O3) -> 3 | L3: =IF(J3>K3,J3,K3) -> 3 | M3: =Scores!T3+Scores!V3 -> 4 | N3: =Scores!U3+Scores!V3 -> 2 | O3: =IF(M3>N3,M3,N3) -> 4 | P3: =IF(B3=0," ",IF(B3=Extra!$S$2,VLOOKUP(C3,Extra!$R$4:$AD$8,O3+1),IF(B3=Extra!$W$2,VLOOKUP(C3,Extra!$R$4:$AD$8,(O3+5)),IF(B3=Extra!$AA$2,VLOOKUP(C3,Extra!$R$4:$AD$8,(O3+9)),0)))) -> 9 | Q3: =IF(I3=0," ",IF(I3=Extra!$S$10,VLOOKUP(F3,Extra!$R$12:$X$17,L3+1),IF(I3=Extra!$V$10,VLOOKUP(F3,Extra!$R$12:$X$17,(L3+4)),0))) -> 8 | R3: =SUM(P3:P28)/26 -> 4.7307692 | S3: =SUM(Q3:Q28)/26 -> 2.3846154 | T3: =$R$3+3 -> 7.7307692 | U3: =S3+2 -> 4.3846154 | V3: =VLOOKUP(ROUND($T3,0),Extra!$S$21:$AE$32,ROUND($U3,0)+1) -> 9 | W3: =V3+1 -> 10
A4: =Angles!A4 -> 2 | B4: =IF(A4=0,0,IF(Scores!B4+Scores!C4+Scores!D4=1,1,IF(Scores!B4+Scores!C4+Scores!D4=2,2,IF(Scores!B4+Scores!C4+Scores!D4>=3,3,0)))) -> 3 | C4: =Scores!E4+Scores!F4+Scores!G4 -> 4 | D4: =Scores!H4+Scores!I4 -> 4 | E4: =Scores!J4+Scores!K4 -> 2 | F4: =IF(D4>E4,D4,E4) -> 4 | G4: =Scores!L4 -> 2 | H4: =Scores!N4 -> 1 | I4: =IF(A4=0,0,IF(G4>H4,G4,H4)) -> 2 | J4: =Scores!P4+MAX(Scores!Q4,Scores!M4) -> 1 | K4: =Scores!R4+MAX(Scores!S4,Scores!O4) -> 3 | L4: =IF(J4>K4,J4,K4) -> 3 | M4: =Scores!T4+Scores!V4 -> 2 | N4: =Scores!U4+Scores!V4 -> 3 | O4: =IF(M4>N4,M4,N4) -> 3 | P4: =IF(B4=0," ",IF(B4=Extra!$S$2,VLOOKUP(C4,Extra!$R$4:$AD$8,O4+1),IF(B4=Extra!$W$2,VLOOKUP(C4,Extra!$R$4:$AD$8,(O4+5)),IF(B4=Extra!$AA$2,VLOOKUP(C4,Extra!$R$4:$AD$8,(O4+9)),0)))) -> 8 | Q4: =IF(I4=0," ",IF(I4=Extra!$S$10,VLOOKUP(F4,Extra!$R$12:$X$17,L4+1),IF(I4=Extra!$V$10,VLOOKUP(F4,Extra!$R$12:$X$17,(L4+4)),0))) -> 7
A5: =Angles!A5 -> 3 | B5: =IF(A5=0,0,IF(Scores!B5+Scores!C5+Scores!D5=1,1,IF(Scores!B5+Scores!C5+Scores!D5=2,2,IF(Scores!B5+Scores!C5+Scores!D5>=3,3,0)))) -> 3 | C5: =Scores!E5+Scores!F5+Scores!G5 -> 4 | D5: =Scores!H5+Scores!I5 -> 4 | E5: =Scores!J5+Scores!K5 -> 2 | F5: =IF(D5>E5,D5,E5) -> 4 | G5: =Scores!L5 -> 1 | H5: =Scores!N5 -> 1 | I5: =IF(A5=0,0,IF(G5>H5,G5,H5)) -> 1 | J5: =Scores!P5+MAX(Scores!Q5,Scores!M5) -> 1 | K5: =Scores!R5+MAX(Scores!S5,Scores!O5) -> 3 | L5: =IF(J5>K5,J5,K5) -> 3 | M5: =Scores!T5+Scores!V5 -> 2 | N5: =Scores!U5+Scores!V5 -> 3 | O5: =IF(M5>N5,M5,N5) -> 3 | P5: =IF(B5=0," ",IF(B5=Extra!$S$2,VLOOKUP(C5,Extra!$R$4:$AD$8,O5+1),IF(B5=Extra!$W$2,VLOOKUP(C5,Extra!$R$4:$AD$8,(O5+5)),IF(B5=Extra!$AA$2,VLOOKUP(C5,Extra!$R$4:$AD$8,(O5+9)),0)))) -> 8 | Q5: =IF(I5=0," ",IF(I5=Extra!$S$10,VLOOKUP(F5,Extra!$R$12:$X$17,L5+1),IF(I5=Extra!$V$10,VLOOKUP(F5,Extra!$R$12:$X$17,(L5+4)),0))) -> 5
A6: =Angles!A6 -> 4 | B6: =IF(A6=0,0,IF(Scores!B6+Scores!C6+Scores!D6=1,1,IF(Scores!B6+Scores!C6+Scores!D6=2,2,IF(Scores!B6+Scores!C6+Scores!D6>=3,3,0)))) -> 3 | C6: =Scores!E6+Scores!F6+Scores!G6 -> 4 | D6: =Scores!H6+Scores!I6 -> 4 | E6: =Scores!J6+Scores!K6 -> 2 | F6: =IF(D6>E6,D6,E6) -> 4 | G6: =Scores!L6 -> 1 | H6: =Scores!N6 -> 1 | I6: =IF(A6=0,0,IF(G6>H6,G6,H6)) -> 1 | J6: =Scores!P6+MAX(Scores!Q6,Scores!M6) -> 1 | K6: =Scores!R6+MAX(Scores!S6,Scores!O6) -> 2 | L6: =IF(J6>K6,J6,K6) -> 2 | M6: =Scores!T6+Scores!V6 -> 2 | N6: =Scores!U6+Scores!V6 -> 3 | O6: =IF(M6>N6,M6,N6) -> 3 | P6: =IF(B6=0," ",IF(B6=Extra!$S$2,VLOOKUP(C6,Extra!$R$4:$AD$8,O6+1),IF(B6=Extra!$W$2,VLOOKUP(C6,Extra!$R$4:$AD$8,(O6+5)),IF(B6=Extra!$AA$2,VLOOKUP(C6,Extra!$R$4:$AD$8,(O6+9)),0)))) -> 8 | Q6: =IF(I6=0," ",IF(I6=Extra!$S$10,VLOOKUP(F6,Extra!$R$12:$X$17,L6+1),IF(I6=Extra!$V$10,VLOOKUP(F6,Extra!$R$12:$X$17,(L6+4)),0))) -> 5
A7: =Angles!A7 -> 5 | B7: =IF(A7=0,0,IF(Scores!B7+Scores!C7+Scores!D7=1,1,IF(Scores!B7+Scores!C7+Scores!D7=2,2,IF(Scores!B7+Scores!C7+Scores!D7>=3,3,0)))) -> 3 | C7: =Scores!E7+Scores!F7+Scores!G7 -> 4 | D7: =Scores!H7+Scores!I7 -> 4 | E7: =Scores!J7+Scores!K7 -> 2 | F7: =IF(D7>E7,D7,E7) -> 4 | G7: =Scores!L7 -> 1 | H7: =Scores!N7 -> 1 | I7: =IF(A7=0,0,IF(G7>H7,G7,H7)) -> 1 | J7: =Scores!P7+MAX(Scores!Q7,Scores!M7) -> 1 | K7: =Scores!R7+MAX(Scores!S7,Scores!O7) -> 2 | L7: =IF(J7>K7,J7,K7) -> 2 | M7: =Scores!T7+Scores!V7 -> 1 | N7: =Scores!U7+Scores!V7 -> 2 | O7: =IF(M7>N7,M7,N7) -> 2 | P7: =IF(B7=0," ",IF(B7=Extra!$S$2,VLOOKUP(C7,Extra!$R$4:$AD$8,O7+1),IF(B7=Extra!$W$2,VLOOKUP(C7,Extra!$R$4:$AD$8,(O7+5)),IF(B7=Extra!$AA$2,VLOOKUP(C7,Extra!$R$4:$AD$8,(O7+9)),0)))) -> 7 | Q7: =IF(I7=0," ",IF(I7=Extra!$S$10,VLOOKUP(F7,Extra!$R$12:$X$17,L7+1),IF(I7=Extra!$V$10,VLOOKUP(F7,Extra!$R$12:$X$17,(L7+4)),0))) -> 5
A8: =Angles!A8 -> 6 | B8: =IF(A8=0,0,IF(Scores!B8+Scores!C8+Scores!D8=1,1,IF(Scores!B8+Scores!C8+Scores!D8=2,2,IF(Scores!B8+Scores!C8+Scores!D8>=3,3,0)))) -> 3 | C8: =Scores!E8+Scores!F8+Scores!G8 -> 2 | D8: =Scores!H8+Scores!I8 -> 1 | E8: =Scores!J8+Scores!K8 -> 2 | F8: =IF(D8>E8,D8,E8) -> 2 | G8: =Scores!L8 -> 1 | H8: =Scores!N8 -> 1 | I8: =IF(A8=0,0,IF(G8>H8,G8,H8)) -> 1 | J8: =Scores!P8+MAX(Scores!Q8,Scores!M8) -> 1 | K8: =Scores!R8+MAX(Scores!S8,Scores!O8) -> 2 | L8: =IF(J8>K8,J8,K8) -> 2 | M8: =Scores!T8+Scores!V8 -> 1 | N8: =Scores!U8+Scores!V8 -> 2 | O8: =IF(M8>N8,M8,N8) -> 2 | P8: =IF(B8=0," ",IF(B8=Extra!$S$2,VLOOKUP(C8,Extra!$R$4:$AD$8,O8+1),IF(B8=Extra!$W$2,VLOOKUP(C8,Extra!$R$4:$AD$8,(O8+5)),IF(B8=Extra!$AA$2,VLOOKUP(C8,Extra!$R$4:$AD$8,(O8+9)),0)))) -> 5 | Q8: =IF(I8=0," ",IF(I8=Extra!$S$10,VLOOKUP(F8,Extra!$R$12:$X$17,L8+1),IF(I8=Extra!$V$10,VLOOKUP(F8,Extra!$R$12:$X$17,(L8+4)),0))) -> 2
A9: =Angles!A9 -> 7 | B9: =IF(A9=0,0,IF(Scores!B9+Scores!C9+Scores!D9=1,1,IF(Scores!B9+Scores!C9+Scores!D9=2,2,IF(Scores!B9+Scores!C9+Scores!D9>=3,3,0)))) -> 3 | C9: =Scores!E9+Scores!F9+Scores!G9 -> 2 | D9: =Scores!H9+Scores!I9 -> 1 | E9: =Scores!J9+Scores!K9 -> 2 | F9: =IF(D9>E9,D9,E9) -> 2 | G9: =Scores!L9 -> 1 | H9: =Scores!N9 -> 1 | I9: =IF(A9=0,0,IF(G9>H9,G9,H9)) -> 1 | J9: =Scores!P9+MAX(Scores!Q9,Scores!M9) -> 1 | K9: =Scores!R9+MAX(Scores!S9,Scores!O9) -> 2 | L9: =IF(J9>K9,J9,K9) -> 2 | M9: =Scores!T9+Scores!V9 -> 1 | N9: =Scores!U9+Scores!V9 -> 2 | O9: =IF(M9>N9,M9,N9) -> 2 | P9: =IF(B9=0," ",IF(B9=Extra!$S$2,VLOOKUP(C9,Extra!$R$4:$AD$8,O9+1),IF(B9=Extra!$W$2,VLOOKUP(C9,Extra!$R$4:$AD$8,(O9+5)),IF(B9=Extra!$AA$2,VLOOKUP(C9,Extra!$R$4:$AD$8,(O9+9)),0)))) -> 5 | Q9: =IF(I9=0," ",IF(I9=Extra!$S$10,VLOOKUP(F9,Extra!$R$12:$X$17,L9+1),IF(I9=Extra!$V$10,VLOOKUP(F9,Extra!$R$12:$X$17,(L9+4)),0))) -> 2
A10: =Angles!A10 -> 8 | B10: =IF(A10=0,0,IF(Scores!B10+Scores!C10+Scores!D10=1,1,IF(Scores!B10+Scores!C10+Scores!D10=2,2,IF(Scores!B10+Scores!C10+Scores!D10>=3,3,0)))) -> 3 | C10: =Scores!E10+Scores!F10+Scores!G10 -> 2 | D10: =Scores!H10+Scores!I10 -> 1 | E10: =Scores!J10+Scores!K10 -> 2 | F10: =IF(D10>E10,D10,E10) -> 2 | G10: =Scores!L10 -> 1 | H10: =Scores!N10 -> 1 | I10: =IF(A10=0,0,IF(G10>H10,G10,H10)) -> 1 | J10: =Scores!P10+MAX(Scores!Q10,Scores!M10) -> 1 | K10: =Scores!R10+MAX(Scores!S10,Scores!O10) -> 2 | L10: =IF(J10>K10,J10,K10) -> 2 | M10: =Scores!T10+Scores!V10 -> 1 | N10: =Scores!U10+Scores!V10 -> 2 | O10: =IF(M10>N10,M10,N10) -> 2 | P10: =IF(B10=0," ",IF(B10=Extra!$S$2,VLOOKUP(C10,Extra!$R$4:$AD$8,O10+1),IF(B10=Extra!$W$2,VLOOKUP(C10,Extra!$R$4:$AD$8,(O10+5)),IF(B10=Extra!$AA$2,VLOOKUP(C10,Extra!$R$4:$AD$8,(O10+9)),0)))) -> 5 | Q10: =IF(I10=0," ",IF(I10=Extra!$S$10,VLOOKUP(F10,Extra!$R$12:$X$17,L10+1),IF(I10=Extra!$V$10,VLOOKUP(F10,Extra!$R$12:$X$17,(L10+4)),0))) -> 2
A11: =Angles!A11 -> 9 | B11: =IF(A11=0,0,IF(Scores!B11+Scores!C11+Scores!D11=1,1,IF(Scores!B11+Scores!C11+Scores!D11=2,2,IF(Scores!B11+Scores!C11+Scores!D11>=3,3,0)))) -> 3 | C11: =Scores!E11+Scores!F11+Scores!G11 -> 2 | D11: =Scores!H11+Scores!I11 -> 1 | E11: =Scores!J11+Scores!K11 -> 2 | F11: =IF(D11>E11,D11,E11) -> 2 | G11: =Scores!L11 -> 1 | H11: =Scores!N11 -> 1 | I11: =IF(A11=0,0,IF(G11>H11,G11,H11)) -> 1 | J11: =Scores!P11+MAX(Scores!Q11,Scores!M11) -> 1 | K11: =Scores!R11+MAX(Scores!S11,Scores!O11) -> 2 | L11: =IF(J11>K11,J11,K11) -> 2 | M11: =Scores!T11+Scores!V11 -> 1 | N11: =Scores!U11+Scores!V11 -> 2 | O11: =IF(M11>N11,M11,N11) -> 2 | P11: =IF(B11=0," ",IF(B11=Extra!$S$2,VLOOKUP(C11,Extra!$R$4:$AD$8,O11+1),IF(B11=Extra!$W$2,VLOOKUP(C11,Extra!$R$4:$AD$8,(O11+5)),IF(B11=Extra!$AA$2,VLOOKUP(C11,Extra!$R$4:$AD$8,(O11+9)),0)))) -> 5 | Q11: =IF(I11=0," ",IF(I11=Extra!$S$10,VLOOKUP(F11,Extra!$R$12:$X$17,L11+1),IF(I11=Extra!$V$10,VLOOKUP(F11,Extra!$R$12:$X$17,(L11+4)),0))) -> 2
A12: =Angles!A12 -> 10 | B12: =IF(A12=0,0,IF(Scores!B12+Scores!C12+Scores!D12=1,1,IF(Scores!B12+Scores!C12+Scores!D12=2,2,IF(Scores!B12+Scores!C12+Scores!D12>=3,3,0)))) -> 3 | C12: =Scores!E12+Scores!F12+Scores!G12 -> 1 | D12: =Scores!H12+Scores!I12 -> 1 | E12: =Scores!J12+Scores!K12 -> 2 | F12: =IF(D12>E12,D12,E12) -> 2 | G12: =Scores!L12 -> 1 | H12: =Scores!N12 -> 1 | I12: =IF(A12=0,0,IF(G12>H12,G12,H12)) -> 1 | J12: =Scores!P12+MAX(Scores!Q12,Scores!M12) -> 1 | K12: =Scores!R12+MAX(Scores!S12,Scores!O12) -> 2 | L12: =IF(J12>K12,J12,K12) -> 2 | M12: =Scores!T12+Scores!V12 -> 1 | N12: =Scores!U12+Scores!V12 -> 2 | O12: =IF(M12>N12,M12,N12) -> 2 | P12: =IF(B12=0," ",IF(B12=Extra!$S$2,VLOOKUP(C12,Extra!$R$4:$AD$8,O12+1),IF(B12=Extra!$W$2,VLOOKUP(C12,Extra!$R$4:$AD$8,(O12+5)),IF(B12=Extra!$AA$2,VLOOKUP(C12,Extra!$R$4:$AD$8,(O12+9)),0)))) -> 3 | Q12: =IF(I12=0," ",IF(I12=Extra!$S$10,VLOOKUP(F12,Extra!$R$12:$X$17,L12+1),IF(I12=Extra!$V$10,VLOOKUP(F12,Extra!$R$12:$X$17,(L12+4)),0))) -> 2
A13: =Angles!A13 -> 11 | B13: =IF(A13=0,0,IF(Scores!B13+Scores!C13+Scores!D13=1,1,IF(Scores!B13+Scores!C13+Scores!D13=2,2,IF(Scores!B13+Scores!C13+Scores!D13>=3,3,0)))) -> 3 | C13: =Scores!E13+Scores!F13+Scores!G13 -> 1 | D13: =Scores!H13+Scores!I13 -> 1 | E13: =Scores!J13+Scores!K13 -> 2 | F13: =IF(D13>E13,D13,E13) -> 2 | G13: =Scores!L13 -> 1 | H13: =Scores!N13 -> 1 | I13: =IF(A13=0,0,IF(G13>H13,G13,H13)) -> 1 | J13: =Scores!P13+MAX(Scores!Q13,Scores!M13) -> 1 | K13: =Scores!R13+MAX(Scores!S13,Scores!O13) -> 2 | L13: =IF(J13>K13,J13,K13) -> 2 | M13: =Scores!T13+Scores!V13 -> 1 | N13: =Scores!U13+Scores!V13 -> 2 | O13: =IF(M13>N13,M13,N13) -> 2 | P13: =IF(B13=0," ",IF(B13=Extra!$S$2,VLOOKUP(C13,Extra!$R$4:$AD$8,O13+1),IF(B13=Extra!$W$2,VLOOKUP(C13,Extra!$R$4:$AD$8,(O13+5)),IF(B13=Extra!$AA$2,VLOOKUP(C13,Extra!$R$4:$AD$8,(O13+9)),0)))) -> 3 | Q13: =IF(I13=0," ",IF(I13=Extra!$S$10,VLOOKUP(F13,Extra!$R$12:$X$17,L13+1),IF(I13=Extra!$V$10,VLOOKUP(F13,Extra!$R$12:$X$17,(L13+4)),0))) -> 2
A14: =Angles!A14 -> 12 | B14: =IF(A14=0,0,IF(Scores!B14+Scores!C14+Scores!D14=1,1,IF(Scores!B14+Scores!C14+Scores!D14=2,2,IF(Scores!B14+Scores!C14+Scores!D14>=3,3,0)))) -> 1 | C14: =Scores!E14+Scores!F14+Scores!G14 -> 1 | D14: =Scores!H14+Scores!I14 -> 1 | E14: =Scores!J14+Scores!K14 -> 2 | F14: =IF(D14>E14,D14,E14) -> 2 | G14: =Scores!L14 -> 1 | H14: =Scores!N14 -> 1 | I14: =IF(A14=0,0,IF(G14>H14,G14,H14)) -> 1 | J14: =Scores!P14+MAX(Scores!Q14,Scores!M14) -> 1 | K14: =Scores!R14+MAX(Scores!S14,Scores!O14) -> 1 | L14: =IF(J14>K14,J14,K14) -> 1 | M14: =Scores!T14+Scores!V14 -> 1 | N14: =Scores!U14+Scores!V14 -> 2 | O14: =IF(M14>N14,M14,N14) -> 2 | P14: =IF(B14=0," ",IF(B14=Extra!$S$2,VLOOKUP(C14,Extra!$R$4:$AD$8,O14+1),IF(B14=Extra!$W$2,VLOOKUP(C14,Extra!$R$4:$AD$8,(O14+5)),IF(B14=Extra!$AA$2,VLOOKUP(C14,Extra!$R$4:$AD$8,(O14+9)),0)))) -> 2 | Q14: =IF(I14=0," ",IF(I14=Extra!$S$10,VLOOKUP(F14,Extra!$R$12:$X$17,L14+1),IF(I14=Extra!$V$10,VLOOKUP(F14,Extra!$R$12:$X$17,(L14+4)),0))) -> 1
A15: =Angles!A15 -> 13 | B15: =IF(A15=0,0,IF(Scores!B15+Scores!C15+Scores!D15=1,1,IF(Scores!B15+Scores!C15+Scores!D15=2,2,IF(Scores!B15+Scores!C15+Scores!D15>=3,3,0)))) -> 1 | C15: =Scores!E15+Scores!F15+Scores!G15 -> 1 | D15: =Scores!H15+Scores!I15 -> 1 | E15: =Scores!J15+Scores!K15 -> 2 | F15: =IF(D15>E15,D15,E15) -> 2 | G15: =Scores!L15 -> 1 | H15: =Scores!N15 -> 1 | I15: =IF(A15=0,0,IF(G15>H15,G15,H15)) -> 1 | J15: =Scores!P15+MAX(Scores!Q15,Scores!M15) -> 1 | K15: =Scores!R15+MAX(Scores!S15,Scores!O15) -> 1 | L15: =IF(J15>K15,J15,K15) -> 1 | M15: =Scores!T15+Scores!V15 -> 1 | N15: =Scores!U15+Scores!V15 -> 2 | O15: =IF(M15>N15,M15,N15) -> 2 | P15: =IF(B15=0," ",IF(B15=Extra!$S$2,VLOOKUP(C15,Extra!$R$4:$AD$8,O15+1),IF(B15=Extra!$W$2,VLOOKUP(C15,Extra!$R$4:$AD$8,(O15+5)),IF(B15=Extra!$AA$2,VLOOKUP(C15,Extra!$R$4:$AD$8,(O15+9)),0)))) -> 2 | Q15: =IF(I15=0," ",IF(I15=Extra!$S$10,VLOOKUP(F15,Extra!$R$12:$X$17,L15+1),IF(I15=Extra!$V$10,VLOOKUP(F15,Extra!$R$12:$X$17,(L15+4)),0))) -> 1
... A28: =Angles!A28 -> 26 | B28: =IF(A28=0,0,IF(Scores!B28+Scores!C28+Scores!D28=1,1,IF(Scores!B28+Scores!C28+Scores!D28=2,2,IF(Scores!B28+Scores!C28+Scores!D28>=3,3,0)))) -> 2 | C28: =Scores!E28+Scores!F28+Scores!G28 -> 2 | D28: =Scores!H28+Scores!I28 -> 2 | E28: =Scores!J28+Scores!K28 -> 2 | F28: =IF(D28>E28,D28,E28) -> 2 | G28: =Scores!L28 -> 1 | H28: =Scores!N28 -> 1 | I28: =IF(A28=0,0,IF(G28>H28,G28,H28)) -> 1 | J28: =Scores!P28+MAX(Scores!Q28,Scores!M28) -> 2 | K28: =Scores!R28+MAX(Scores!S28,Scores!O28) -> 2 | L28: =IF(J28>K28,J28,K28) -> 2 | M28: =Scores!T28+Scores!V28 -> 3 | N28: =Scores!U28+Scores!V28 -> 4 | O28: =IF(M28>N28,M28,N28) -> 4 | P28: =IF(B28=0," ",IF(B28=Extra!$S$2,VLOOKUP(C28,Extra!$R$4:$AD$8,O28+1),IF(B28=Extra!$W$2,VLOOKUP(C28,Extra!$R$4:$AD$8,(O28+5)),IF(B28=Extra!$AA$2,VLOOKUP(C28,Extra!$R$4:$AD$8,(O28+9)),0)))) -> 6 | Q28: =IF(I28=0," ",IF(I28=Extra!$S$10,VLOOKUP(F28,Extra!$R$12:$X$17,L28+1),IF(I28=Extra!$V$10,VLOOKUP(F28,Extra!$R$12:$X$17,(L28+4)),0))) -> 2

Sheet Extra
A1: Tabella A | B1: + | C1: Forza | D1: TOT A | F1: Tabella B | G1: + | H1: Impugnatura | I1: TOT B | K1: Tabella C | L1: + | M1: Ripetitività | O1: REBA SCORE | R1: Table A | S1: REBA | AH1: 0
A2: =AVERAGE(Reba!P3:P999) -> 4.7307692 | C2: 0 | D2: =A2+C2 -> 4.7307692 | F2: =AVERAGE(Reba!Q3:Q999) -> 2.3846154 | H2: 0 | I2: =F2+H2 -> 2.3846154 | K2: =VLOOKUP($D$2,$S$21:$AE$32,$I$2+1) -> 4 | M2: 0 | O2: =K2+M2 -> 4 | S2: 1 | T2: 1 | U2: 1 | V2: 1 | W2: 2 | X2: 2 | Y2: 2 | Z2: 2 | AA2: 3 | AB2: 3 | AC2: 3 | AD2: 3 | AE2: Neck | AH2: 1
R3: Trunk | S3: 1 | T3: 2 | U3: 3 | V3: 4 | W3: 1 | X3: 2 | Y3: 3 | Z3: 4 | AA3: 1 | AB3: 2 | AC3: 3 | AD3: 4 | AE3: Legs | AH3: 2
R4: 1 | S4: 1 | T4: 2 | U4: 3 | V4: 4 | W4: 1 | X4: 2 | Y4: 3 | Z4: 4 | AA4: 3 | AB4: 3 | AC4: 5 | AD4: 6 | AH4: 3
R5: 2 | S5: 2 | T5: 3 | U5: 4 | V5: 5 | W5: 3 | X5: 4 | Y5: 5 | Z5: 6 | AA5: 4 | AB5: 5 | AC5: 6 | AD5: 7
R6: 3 | S6: 2 | T6: 4 | U6: 5 | V6: 6 | W6: 4 | X6: 5 | Y6: 6 | Z6: 7 | AA6: 5 | AB6: 6 | AC6: 7 | AD6: 8
R7: 4 | S7: 3 | T7: 5 | U7: 6 | V7: 7 | W7: 5 | X7: 6 | Y7: 7 | Z7: 8 | AA7: 6 | AB7: 7 | AC7: 8 | AD7: 9
R8: 5 | S8: 4 | T8: 6 | U8: 7 | V8: 8 | W8: 6 | X8: 7 | Y8: 8 | Z8: 9 | AA8: 7 | AB8: 8 | AC8: 9 | AD8: 9
R9: Table B | S9: REBA
S10: 1 | T10: 1 | U10: 1 | V10: 2 | W10: 2 | X10: 2 | Y10: Lower Arm
R11: Upper Arm | S11: 1 | T11: 2 | U11: 3 | V11: 1 | W11: 2 | X11: 3 | Y11: Wrist
R12: 1 | S12: 1 | T12: 2 | U12: 2 | V12: 1 | W12: 2 | X12: 3
R13: 2 | S13: 1 | T13: 2 | U13: 3 | V13: 2 | W13: 3 | X13: 4
R14: 3 | S14: 3 | T14: 4 | U14: 5 | V14: 4 | W14: 5 | X14: 5
R15: 4 | S15: 4 | T15: 5 | U15: 5 | V15: 5 | W15: 6 | X15: 7
R16: 5 | S16: 6 | T16: 7 | U16: 8 | V16: 7 | W16: 8 | X16: 8
R17: 6 | S17: 7 | T17: 8 | U17: 8 | V17: 8 | W17: 9 | X17: 9
S19: Table C | T19: REBA | W19: Score B
T20: 1 | U20: 2 | V20: 3 | W20: 4 | X20: 5 | Y20: 6 | Z20: 7 | AA20: 8 | AB20: 9 | AC20: 10 | AD20: 11 | AE20: 12
S21: 1 | T21: 1 | U21: 1 | V21: 1 | W21: 2 | X21: 3 | Y21: 3 | Z21: 4 | AA21: 5 | AB21: 6 | AC21: 7 | AD21: 7 | AE21: 7
R22: S | S22: 2 | T22: 1 | U22: 2 | V22: 2 | W22: 3 | X22: 4 | Y22: 4 | Z22: 5 | AA22: 6 | AB22: 6 | AC22: 7 | AD22: 7 | AE22: 8
R23: c | S23: 3 | T23: 2 | U23: 3 | V23: 3 | W23: 3 | X23: 4 | Y23: 5 | Z23: 6 | AA23: 7 | AB23: 7 | AC23: 8 | AD23: 8 | AE23: 8
R24: c | S24: 4 | T24: 3 | U24: 4 | V24: 4 | W24: 4 | X24: 5 | Y24: 6 | Z24: 7 | AA24: 8 | AB24: 8 | AC24: 9 | AD24: 9 | AE24: 9
R25: r | S25: 5 | T25: 4 | U25: 4 | V25: 4 | W25: 5 | X25: 6 | Y25: 7 | Z25: 8 | AA25: 8 | AB25: 9 | AC25: 9 | AD25: 9 | AE25: 9
R26: e | S26: 6 | T26: 6 | U26: 6 | V26: 6 | W26: 7 | X26: 8 | Y26: 8 | Z26: 9 | AA26: 9 | AB26: 10 | AC26: 10 | AD26: 10 | AE26: 10
S27: 7 | T27: 7 | U27: 7 | V27: 7 | W27: 8 | X27: 9 | Y27: 9 | Z27: 9 | AA27: 10 | AB27: 10 | AC27: 11 | AD27: 11 | AE27: 11
R28: A | S28: 8 | T28: 8 | U28: 8 | V28: 8 | W28: 9 | X28: 10 | Y28: 10 | Z28: 10 | AA28: 10 | AB28: 10 | AC28: 11 | AD28: 11 | AE28: 11
S29: 9 | T29: 9 | U29: 9 | V29: 9 | W29: 10 | X29: 10 | Y29: 10 | Z29: 11 | AA29: 11 | AB29: 11 | AC29: 12 | AD29: 12 | AE29: 12
S30: 10 | T30: 10 | U30: 10 | V30: 10 | W30: 11 | X30: 11 | Y30: 11 | Z30: 11 | AA30: 12 | AB30: 12 | AC30: 12 | AD30: 12 | AE30: 12
S31: 11 | T31: 11 | U31: 11 | V31: 11 | W31: 11 | X31: 11 | Y31: 12 | Z31: 12 | AA31: 12 | AB31: 12 | AC31: 12 | AD31: 12 | AE31: 12
S32: 12 | T32: 12 | U32: 12 | V32: 12 | W32: 12 | X32: 12 | Y32: 12 | Z32: 12 | AA32: 12 | AB32: 12 | AC32: 12 | AD32: 12 | AE32: 12

Sheet Base
B1: A. Neck, Trunk and Leg Analysis | L1: SCORES | V1: B: Arms and Wrist Analysis
A2: Step 1: Locate Neck Position | F2: Table A | G2: Neck | U2: Step 7: Locate Upper Arm Position:
H3: 1 | L3: 2 | P3: 3
G4: Legs
H5: 1 | I5: 2 | J5: 3 | K5: 4 | L5: 1 | M5: 2 | N5: 3 | O5: 4 | P5: 1 | Q5: 2 | R5: 3 | S5: 4
F6: Trunk Posture Score | G6: 1 | H6: 1 | I6: 2 | J6: 3 | K6: 4 | L6: 1 | M6: 2 | N6: 3 | O6: 5 | P6: 3 | Q6: 3 | R6: 5 | S6: 6
G7: 2 | H7: 2 | I7: 3 | J7: 4 | K7: 5 | L7: 3 | M7: 4 | N7: 5 | O7: 6 | P7: 4 | Q7: 5 | R7: 6 | S7: 7
A8: Step 1a Adjust…. | E8: Neck Score | G8: 3 | H8: 2 | I8: 4 | J8: 5 | K8: 6 | L8: 4 | M8: 5 | N8: 6 | O8: 7 | P8: 5 | Q8: 6 | R8: 7 | S8: 8
A9: If neck is twisted: +1 | G9: 4 | H9: 3 | I9: 5 | J9: 6 | K9: 7 | L9: 5 | M9: 6 | N9: 7 | O9: 8 | P9: 6 | Q9: 7 | R9: 8 | S9: 9 | U9: Step 7a: Adjust….
A10: If neck is side bending: +1 | G10: 5 | H10: 4 | I10: 6 | J10: 7 | K10: 8 | L10: 6 | M10: 7 | N10: 8 | O10: 9 | P10: 7 | Q10: 8 | R10: 9 | S10: 9 | U10: If shoulder is raised: +1
U11: If Upper Arm is abducted: +1 | Z11: Upper Arm Score
A12: Step 2: Locate Trunk Position | F12: Table B | G12: Lower Arm | U12: If arm is supported or leaning: -1
H13: 1 | K13: 2
G14: Wrist
H15: 1 | I15: 2 | J15: 3 | K15: 1 | L15: 2 | M15: 3 | U15: Step 8: Locate Lower Arm Position:
F16: Upper Arm Score | G16: 1 | H16: 1 | I16: 2 | J16: 2 | K16: 1 | L16: 2 | M16: 3
G17: 2 | H17: 1 | I17: 2 | J17: 3 | K17: 2 | L17: 3 | M17: 4
A18: Step 2a: Adjust…. | G18: 3 | H18: 3 | I18: 4 | J18: 5 | K18: 4 | L18: 5 | M18: 5
A19: If trunk is twisted: +1 | G19: 4 | H19: 4 | I19: 5 | J19: 5 | K19: 5 | L19: 6 | M19: 7 | Z19: Lower Arm Score
A20: If trunk is side bending: +1 | E20: Trunk Score | G20: 5 | H20: 6 | I20: 7 | J20: 8 | K20: 7 | L20: 8 | M20: 8
G21: 6 | H21: 7 | I21: 8 | J21: 8 | K21: 8 | L21: 9 | M21: 9
A22: Step 3: Legs | U22: Step 9: Locate Wrist Position:
F23: Score A (score form table A +load/force score) | G23: Table C
G24: Score B, (table B value + coupling score)
G26: 1 | H26: 2 | I26: 3 | J26: 4 | K26: 5 | L26: 6 | M26: 7 | N26: 8 | O26: 9 | P26: 10 | Q26: 11 | R26: 12 | Z26: Wrist Score
E27: Leg Score | F27: 1 | G27: 1 | H27: 1 | I27: 1 | J27: 2 | K27: 3 | L27: 3 | M27: 4 | N27: 5 | O27: 6 | P27: 7 | Q27: 7 | R27: 7 | U27: Step 9a: Adjust……
F28: 2 | G28: 1 | H28: 2 | I28: 2 | J28: 3 | K28: 4 | L28: 4 | M28: 5 | N28: 6 | O28: 6 | P28: 7 | Q28: 7 | R28: 8 | U28: If wrist is bent from midline or twisted: Add +1 | Z28: =Extra!F2 -> 2.3846154
F29: 3 | G29: 2 | H29: 3 | I29: 3 | J29: 3 | K29: 4 | L29: 5 | M29: 6 | N29: 7 | O29: 7 | P29: 8 | Q29: 8 | R29: 8 | U29: Step 10: Look-up Posture Score in Table B:
A30: Step 4: Look-up Posture Score in Table A | E30: =Extra!A2 -> 4.7307692 | F30: 4 | G30: 3 | H30: 4 | I30: 4 | J30: 4 | K30: 5 | L30: 6 | M30: 7 | N30: 8 | O30: 8 | P30: 9 | Q30: 9 | R30: 9 | U30: Using values from steps 7-9 above, locate score in Table B | Z30: Posture Score B
A31: Using values from steps 1-3 above, locate score in | F31: 5 | G31: 4 | H31: 4 | I31: 4 | J31: 5 | K31: 6 | L31: 7 | M31: 8 | N31: 8 | O31: 9 | P31: 9 | Q31: 9 | R31: 9 | U31: Step 11: Add Coupling Score | Z31: +
A32: Table A | E32: Posture Score A | F32: 6 | G32: 6 | H32: 6 | I32: 6 | J32: 7 | K32: 8 | L32: 8 | M32: 9 | N32: 9 | O32: 10 | P32: 10 | Q32: 10 | R32: 10 | U32: Well fitted handles and mid range power grip, good: +0 | Z32: =Extra!H2 -> 0
E33: + | F33: 7 | G33: 7 | H33: 7 | I33: 7 | J33: 8 | K33: 9 | L33: 9 | M33: 9 | N33: 10 | O33: 10 | P33: 11 | Q33: 11 | R33: 11 | U33: Acceptable but not ideal hold or coupling
A34: Step 5: Add Force/Load Score | E34: =Extra!C2 -> 0 | F34: 8 | G34: 8 | H34: 8 | I34: 8 | J34: 9 | K34: 10 | L34: 10 | M34: 10 | N34: 10 | O34: 10 | P34: 11 | Q34: 11 | R34: 11 | U34: acceptable with another body part, fair: +1 | Z34: Coupling Score
A35: If Load < 5kgs: +0 | F35: 9 | G35: 9 | H35: 9 | I35: 9 | J35: 10 | K35: 10 | L35: 10 | M35: 11 | N35: 11 | O35: 11 | P35: 12 | Q35: 12 | R35: 12 | U35: Hand hold not acceptable but possible poor: +2
A36: If Load is 5 to 10kgs +1 | E36: Force/Load Score | F36: 10 | G36: 10 | H36: 10 | I36: 10 | J36: 11 | K36: 11 | L36: 11 | M36: 11 | N36: 12 | O36: 12 | P36: 12 | Q36: 12 | R36: 12 | U36: No handles, awkward, unsafe with any body part, | Z36: =
A37: If load >22lbs +2 | F37: 11 | G37: 11 | H37: 11 | I37: 11 | J37: 11 | K37: 11 | L37: 12 | M37: 12 | N37: 12 | O37: 12 | P37: 12 | Q37: 12 | R37: 12 | U37: Unacceptable: +3
A38: Adjust: If shock or rapid build up of force:add +1 | E38: = | F38: 12 | G38: 12 | H38: 12 | I38: 12 | J38: 12 | K38: 12 | L38: 12 | M38: 12 | N38: 12 | O38: 12 | P38: 12 | Q38: 12 | R38: 12 | U38: Step 12: Score B, Find column in Table C | Z38: =Extra!I2 -> 2.3846154
A39: Step 6: Score A, Find Row in Table C | E39: =Extra!D2 -> 4.7307692 | U39: Add values from steps 10 & 11 to obtain
A40: Add values from steps 4 & 5 to obtain Score A. | F40: =Extra!K2 -> 4 | I40: + | M40: =Extra!M2 -> 0 | U40: Score B> Find Column in Table C and match with Score A in | Z40: Score B
A41: Find row in Table C. | E41: Score A | U41: row from step 6 to obtain Table C score.
...
